Traceback (most recent call last):
  File "/opt/homebrew/Caskroom/miniconda/base/envs/python311/lib/python3.11/site-packages/jupyter_cache/executors/utils.py", line 58, in single_nb_execution
    executenb(
  File "/opt/homebrew/Caskroom/miniconda/base/envs/python311/lib/python3.11/site-packages/nbclient/client.py", line 1204, in execute
    return NotebookClient(nb=nb, resources=resources, km=km, **kwargs).execute()
           ^^^^^^^^^^^^^^^^^^^^^^^^^^^^^^^^^^^^^^^^^^^^^^^^^^^^^^^^^^^^^^^^^^^^^
  File "/opt/homebrew/Caskroom/miniconda/base/envs/python311/lib/python3.11/site-packages/nbclient/util.py", line 84, in wrapped
    return just_run(coro(*args, **kwargs))
           ^^^^^^^^^^^^^^^^^^^^^^^^^^^^^^^
  File "/opt/homebrew/Caskroom/miniconda/base/envs/python311/lib/python3.11/site-packages/nbclient/util.py", line 62, in just_run
    return loop.run_until_complete(coro)
           ^^^^^^^^^^^^^^^^^^^^^^^^^^^^^
  File "/opt/homebrew/Caskroom/miniconda/base/envs/python311/lib/python3.11/asyncio/base_events.py", line 650, in run_until_complete
    return future.result()
           ^^^^^^^^^^^^^^^
  File "/opt/homebrew/Caskroom/miniconda/base/envs/python311/lib/python3.11/contextlib.py", line 222, in __aexit__
    await self.gen.athrow(typ, value, traceback)
  File "/opt/homebrew/Caskroom/miniconda/base/envs/python311/lib/python3.11/site-packages/nbclient/client.py", line 608, in async_setup_kernel
    yield
  File "/opt/homebrew/Caskroom/miniconda/base/envs/python311/lib/python3.11/site-packages/nbclient/client.py", line 663, in async_execute
    await self.async_execute_cell(
  File "/opt/homebrew/Caskroom/miniconda/base/envs/python311/lib/python3.11/site-packages/nbclient/client.py", line 965, in async_execute_cell
    await self._check_raise_for_error(cell, cell_index, exec_reply)
  File "/opt/homebrew/Caskroom/miniconda/base/envs/python311/lib/python3.11/site-packages/nbclient/client.py", line 862, in _check_raise_for_error
    raise CellExecutionError.from_cell_and_msg(cell, exec_reply_content)
nbclient.exceptions.CellExecutionError: An error occurred while executing the following cell:
------------------
import numpy as np
import plotly.graph_objects as go
import plotly.io as pio
pio.renderers.default = "webgl"

# generate grid
r = np.linspace(0, 5, 101)
phi = np.linspace(0, 2*np.pi, 101)
grid_r, grid_phi = np.meshgrid(r, phi) 
x = grid_r * np.cos(grid_phi)
y = grid_r * np.sin(grid_phi)

# evaluate function
z = 0.5 * (x**2 + y**2) 

# plot
fig = go.Figure()
fig.add_trace(go.Surface(z=z, x=x, y=y, colorscale='viridis'))
fig.update_layout(title='Paraboloid f(x,y)=x^2 + y^2', 
xaxis_title='x-Achse', yaxis_title='y-Achse')
------------------

[0;31m---------------------------------------------------------------------------[0m
[0;31mValueError[0m                                Traceback (most recent call last)
Cell [0;32mIn[1], line 4[0m
[1;32m      2[0m [38;5;28;01mimport[39;00m [38;5;21;01mplotly[39;00m[38;5;21;01m.[39;00m[38;5;21;01mgraph_objects[39;00m [38;5;28;01mas[39;00m [38;5;21;01mgo[39;00m
[1;32m      3[0m [38;5;28;01mimport[39;00m [38;5;21;01mplotly[39;00m[38;5;21;01m.[39;00m[38;5;21;01mio[39;00m [38;5;28;01mas[39;00m [38;5;21;01mpio[39;00m
[0;32m----> 4[0m pio[38;5;241m.[39mrenderers[38;5;241m.[39mdefault [38;5;241m=[39m [38;5;124m"[39m[38;5;124mwebgl[39m[38;5;124m"[39m
[1;32m      6[0m [38;5;66;03m# generate grid[39;00m
[1;32m      7[0m r [38;5;241m=[39m np[38;5;241m.[39mlinspace([38;5;241m0[39m, [38;5;241m5[39m, [38;5;241m101[39m)

File [0;32m/opt/homebrew/Caskroom/miniconda/base/envs/python311/lib/python3.11/site-packages/plotly/io/_renderers.py:152[0m, in [0;36mRenderersConfig.default[0;34m(self, value)[0m
[1;32m    149[0m     [38;5;28;01mreturn[39;00m
[1;32m    151[0m [38;5;66;03m# Store defaults name and list of renderer(s)[39;00m
[0;32m--> 152[0m renderer_names [38;5;241m=[39m [38;5;28mself[39m[38;5;241m.[39m_validate_coerce_renderers(value)
[1;32m    153[0m [38;5;28mself[39m[38;5;241m.[39m_default_name [38;5;241m=[39m value
[1;32m    154[0m [38;5;28mself[39m[38;5;241m.[39m_default_renderers [38;5;241m=[39m [[38;5;28mself[39m[name] [38;5;28;01mfor[39;00m name [38;5;129;01min[39;00m renderer_names]

File [0;32m/opt/homebrew/Caskroom/miniconda/base/envs/python311/lib/python3.11/site-packages/plotly/io/_renderers.py:219[0m, in [0;36mRenderersConfig._validate_coerce_renderers[0;34m(self, renderers_string)[0m
[1;32m    217[0m         invalid [38;5;241m=[39m [name [38;5;28;01mfor[39;00m name [38;5;129;01min[39;00m renderer_names [38;5;28;01mif[39;00m name [38;5;129;01mnot[39;00m [38;5;129;01min[39;00m [38;5;28mself[39m]
[1;32m    218[0m         [38;5;28;01mif[39;00m invalid:
[0;32m--> 219[0m             [38;5;28;01mraise[39;00m [38;5;167;01mValueError[39;00m(
[1;32m    220[0m [38;5;250m                [39m[38;5;124;03m"""[39;00m
[1;32m    221[0m [38;5;124;03mInvalid named renderer(s) received: {}"""[39;00m[38;5;241m.[39mformat(
[1;32m    222[0m                     [38;5;28mstr[39m(invalid)
[1;32m    223[0m                 )
[1;32m    224[0m             )
[1;32m    226[0m         [38;5;28;01mreturn[39;00m renderer_names

[0;31mValueError[0m: 
Invalid named renderer(s) received: ['webgl']
ValueError: 
Invalid named renderer(s) received: ['webgl']

